Workbook

Sheet Copy of Copy of Backlog
A1: Effort Willing to Visit | B1: What | C1: One Liner | D1: Longer Description | E1: Accessible | F1: Location | G1: Google Maps Link | H1: Location Category | I1: Cache Entry | J1: Address Component Types | K1: Map Content Dynamically Loaded | L1: City is in Location Description | M1: Coordinates Cached | N1: Lat | O1: Long | P1: City | Q1: State / Region | R1: Postal Code | S1: Country | T1: Drive Distance (Miles) | U1: Drive Time | V1: Absolute Distance (Miles) | W1: Requires Hike? | X1: Hike Distance Roundtrip Miles | Y1: Hike Link | Z1: Last Been | AA1: Activity | AB1: Link 1 | AC1: Link 2 | AD1: Link 3 | AE1: Superlative Liner | AF1: Notes
A2: 7 - Bucket List | B2: Torngat Mountains National Park | C2: This dramatic, otherworldly landscape of sweeping peaks and valleys in Newfoundland and Labrador named for the Inuktitut “Tongait” or “place of the spirits” is remote with a capital R, which is why most travelers never make it there. Here’s why you should. | D2: It’s hard to describe the Torngats without gushing. It’s simply superlative. It’s a place of unusual geology created by some of the world’s oldest rocks. Towering glacier-carved mountains in hues of peach, green, and gray rise up dramatically from river-cut valleys and fjords far below like a cinematographer’s flipside take on Mordor. The place feels brooding, uplifting, and spiritual at the same time. Not surprisingly, it was once the stomping grounds of Inuit shamans. Go to get way out there and experience nature at her most unspoiled; for solitude, rugged adventure, to meet the Aboriginals who live there, and to see creatures like polar bears, whales, and caribou in their pristine natural environment. | F2: Torngat Mountains National Park, Canada | G2: =HYPERLINK(CONCAT("https://www.google.com/maps/search/",F2),"Link") -> Link | H2: Nature | I2: =getCacheString(concat("GMPD|",F2)) -> {"distance_from":{"mi":{"driving":{"2116 4th Ave, Seattle, WA, 98121":"GOOGLE_MAPS_ERROR_CACHED - No route found!"},"flying":{"2116 4th Ave, Seattle, WA, 98121":2442.586401879031}}},"address_components":[{"types":[],"long_name":"Torngat Mountains","short_name":""},{"long_name":"Torngat Mountains National Park","types":["establishment","park","point_of_interest","tourist_attraction"],"short_name":"Torngat Mountains National Park"},{"types":["locality","political"],"long_name":"Nain","short_name":"Nain"},{"short_name":"NL","types":["administrative_area_level_1","political"],"long_name":"Newfoundland and Labrador"},{"long_name":"Canada","short_name":"CA","types":["country","political"]},{"long_name":"A0P 1L0","types":["postal_code"],"short_name":"A0P 1L0"},{"types":["plus_code"],"long_name":"97FR62F4+RM","short_name":"97FR62F4+RM"},{"types":["latitude"],"long_name":59.22460509999999,"short_name":59.22460509999999},{"types":["longitude"],"long_name":-63.99337480000001,"short_name":-63.99337480000001}],"duration_from":{"days":{"driving":{"2116 4th Ave, Seattle, WA, 98121":"GOOGLE_MAPS_ERROR_CACHED - No route found!"}}}} | J2: =GOOGLEMAPS_GET_ADDRESS_COMPONENTS_STRING(F2,false) -> [{"types":[],"long_name":"Torngat Mountains","short_name":""},{"long_name":"Torngat Mountains National Park","types":["establishment","park","point_of_interest","tourist_attraction"],"short_name":"Torngat Mountains National Park"},{"types":["locality","political"],"long_name":"Nain","short_name":"Nain"},{"short_name":"NL","types":["administrative_area_level_1","political"],"long_name":"Newfoundland and Labrador"},{"long_name":"Canada","short_name":"CA","types":["country","political"]},{"long_name":"A0P 1L0","types":["postal_code"],"short_name":"A0P 1L0"},{"types":["plus_code"],"long_name":"97FR62F4+RM","short_name":"97FR62F4+RM"},{"types":["latitude"],"long_name":59.22460509999999,"short_name":59.22460509999999},{"types":["longitude"],"long_name":-63.99337480000001,"short_name":-63.99337480000001},{"types":["debug_info","cache_load_result"],"long_name":"hit","short_name":"hit"}] | K2: =NOT(AND(NOT(_xlfn.ISFORMULA(P2)),AND(NOT(_xlfn.ISFORMULA(Q2)),AND(NOT(_xlfn.ISFORMULA(R2)),AND(NOT(_xlfn.ISFORMULA(S2)),AND(NOT(_xlfn.ISFORMULA(T2)),AND(NOT(_xlfn.ISFORMULA(U2)),AND(NOT(_xlfn.ISFORMULA(V2)))))))))) -> TRUE | L2: =iferror(SEARCH(P2,F2),-1)>=0 -> FALSE | M2: TRUE | N2: =GOOGLEMAPS_GET_ADDRESS_LATITUDE(F2,true) -> 59.224605 | O2: =GOOGLEMAPS_GET_ADDRESS_LONGITUDE(F2,true) -> -63.993375 | P2: =GOOGLEMAPS_GET_ADDRESS_CITY(F2,true,false) -> Nain | Q2: =GOOGLEMAPS_GET_ADDRESS_STATE(F2,true,false) -> Newfoundland and Labrador | R2: =GOOGLEMAPS_GET_ADDRESS_POSTAL_CODE(F2,false,false) -> A0P 1L0 | S2: =GOOGLEMAPS_GET_ADDRESS_COUNTRY(F2,true,false) -> Canada | T2: =IFERROR(GOOGLEMAPS_DISTANCE("2116 4th Ave, Seattle, WA, 98121", F2, "driving")+0,"Not Driveable") -> Not Driveable | U2: =iferror(GOOGLEMAPS_DURATION("2116 4th Ave, Seattle, WA, 98121", F2, "driving")+0,"Not Driveable") -> Not Driveable | V2: =GOOGLEMAPS_DISTANCE("2116 4th Ave, Seattle, WA, 98121", F2, "flying")+0 -> 2442.5864 | X2: =if(W2="YES","UNKNOWN","N/A") -> N/A | Z2: N/A | AB2: https://us-keepexploring.canada.travel/things-to-do/bucket-list-guide-torngat-mountains-national-park
A3: 7 - Bucket List | B3: Centralia | C3: Coal mining town with active fire under it | D3: Centralia was yet another victim of the U.S. decline in mining, but not in the same way as the others on this list. A massive underground coal fire ignited beneath the town in 1962 and it’s been burning ever since. The town’s population plummeted from more than 1,000 in 1980 to less than 10 in 2013. Not surprisingly, the town was subsequently condemned. However, some (clearly insane) residents still call the town home. Due to the dangerous air toxicity and high potential for sinkholes, most of it is strictly off limits. However, that hasn’t stopped the hundreds of “ruin porn”-seeking visitors who visit its decaying streets each year. | E3: 1 – Accessible – Freely | F3: Centralia, PA | G3: =HYPERLINK(CONCAT("https://www.google.com/maps/search/",F3),"Link") -> Link | H3: Ghost Town | I3: =getCacheString(concat("GMPD|",F3)) -> {"address_components":[{"short_name":"Centralia","types":["locality","political"],"long_name":"Centralia"},{"long_name":"Columbia County","short_name":"Columbia County","types":["administrative_area_level_2","political"]},{"long_name":"Pennsylvania","types":["administrative_area_level_1","political"],"short_name":"PA"},{"short_name":"US","types":["country","political"],"long_name":"United States"},{"long_name":"422","short_name":"422","types":["street_number"]},{"long_name":"Locust Avenue","types":["route"],"short_name":"Locust Ave"},{"short_name":"Aristes","long_name":"Aristes","types":["locality","political"]},{"short_name":"Columbia County","long_name":"Columbia County","types":["administrative_area_level_2","political"]},{"short_name":"PA","types":["administrative_area_level_1","political"],"long_name":"Pennsylvania"},{"short_name":"US","types":["country","political"],"long_name":"United States"},{"short_name":"17920","types":["postal_code"],"long_name":"17920"},{"types":["latitude"],"long_name":40.8042541,"short_name":40.8042541},{"types":["longitude"],"long_name":-76.3405035,"short_name":-76.3405035}]} | J3: =GOOGLEMAPS_GET_ADDRESS_COMPONENTS_STRING(F3,false) -> [{"short_name":"Centralia","types":["locality","political"],"long_name":"Centralia"},{"long_name":"Columbia County","short_name":"Columbia County","types":["administrative_area_level_2","political"]},{"long_name":"Pennsylvania","types":["administrative_area_level_1","political"],"short_name":"PA"},{"short_name":"US","types":["country","political"],"long_name":"United States"},{"long_name":"422","short_name":"422","types":["street_number"]},{"long_name":"Locust Avenue","types":["route"],"short_name":"Locust Ave"},{"short_name":"Aristes","long_name":"Aristes","types":["locality","political"]},{"short_name":"Columbia County","long_name":"Columbia County","types":["administrative_area_level_2","political"]},{"short_name":"PA","types":["administrative_area_level_1","political"],"long_name":"Pennsylvania"},{"short_name":"US","types":["country","political"],"long_name":"United States"},{"short_name":"17920","types":["postal_code"],"long_name":"17920"},{"types":["latitude"],"long_name":40.8042541,"short_name":40.8042541},{"types":["longitude"],"long_name":-76.3405035,"short_name":-76.3405035},{"types":["debug_info","cache_load_result"],"long_name":"hit","short_name":"hit"}] | K3: =NOT(AND(NOT(_xlfn.ISFORMULA(P3)),AND(NOT(_xlfn.ISFORMULA(Q3)),AND(NOT(_xlfn.ISFORMULA(R3)),AND(NOT(_xlfn.ISFORMULA(S3)),AND(NOT(_xlfn.ISFORMULA(T3)),AND(NOT(_xlfn.ISFORMULA(U3)),AND(NOT(_xlfn.ISFORMULA(V3)),AND(NOT(_xlfn.ISFORMULA(N3)),NOT(_xlfn.ISFORMULA(O3))))))))))) -> FALSE | L3: =iferror(SEARCH(P3,F3),-1)>=0 -> TRUE | M3: TRUE | N3: 40.804254 | O3: -76.340503 | P3: Centralia | Q3: Pennsylvania | R3: 17920 | S3: United States | T3: 2720 | U3: 1.6646759 | V3: 2291.26 | X3: =if(W3="YES","UNKNOWN","N/A") -> N/A | Z3: N/A | AF3: Mining Town that has an Underground Fire
A4: 7 - Bucket List | B4: Lake Maracaibo | C4: Giant lake with frequent lightning | E4: 1 – Accessible – Freely | F4: Lake Maracaibo, Venezuela | G4: =HYPERLINK(CONCAT("https://www.google.com/maps/search/",F4),"Link") -> Link | H4: Nature | I4: =getCacheString(concat("GMPD|",F4)) -> {"distance_from":{"mi":{"flying":{"2116 4th Ave, Seattle, WA, 98121":3920.1623025588133},"driving":{"2116 4th Ave, Seattle, WA, 98121":"GOOGLE_MAPS_ERROR_CACHED - No route found!"}}},"address_components":[{"short_name":"Lake Maracaibo","types":["establishment","natural_feature"],"long_name":"Lake Maracaibo"},{"long_name":"Venezuela","short_name":"VE","types":["country","political"]},{"long_name":"772C2CHF+46","short_name":"772C2CHF+46","types":["plus_code"]},{"types":["latitude"],"long_name":10.0278,"short_name":10.0278},{"types":["longitude"],"long_name":-71.5769,"short_name":-71.5769}],"duration_from":{"days":{"driving":{"2116 4th Ave, Seattle, WA, 98121":"GOOGLE_MAPS_ERROR_CACHED - No route found!"}}}} | J4: =GOOGLEMAPS_GET_ADDRESS_COMPONENTS_STRING(F4,false) -> [{"short_name":"Lake Maracaibo","types":["establishment","natural_feature"],"long_name":"Lake Maracaibo"},{"long_name":"Venezuela","short_name":"VE","types":["country","political"]},{"long_name":"772C2CHF+46","short_name":"772C2CHF+46","types":["plus_code"]},{"types":["latitude"],"long_name":10.0278,"short_name":10.0278},{"types":["longitude"],"long_name":-71.5769,"short_name":-71.5769},{"types":["debug_info","cache_load_result"],"long_name":"hit","short_name":"hit"}] | K4: =NOT(AND(NOT(_xlfn.ISFORMULA(P4)),AND(NOT(_xlfn.ISFORMULA(Q4)),AND(NOT(_xlfn.ISFORMULA(R4)),AND(NOT(_xlfn.ISFORMULA(S4)),AND(NOT(_xlfn.ISFORMULA(T4)),AND(NOT(_xlfn.ISFORMULA(U4)),AND(NOT(_xlfn.ISFORMULA(V4)))))))))) -> TRUE | L4: =iferror(SEARCH(P4,F4),-1)>=0 -> FALSE | M4: TRUE | N4: =GOOGLEMAPS_GET_ADDRESS_LATITUDE(F4,true) -> 10.0278 | O4: =GOOGLEMAPS_GET_ADDRESS_LONGITUDE(F4,true) -> -71.5769 | P4: =GOOGLEMAPS_GET_ADDRESS_CITY(F4,true,false) -> UNDEFINED | Q4: =GOOGLEMAPS_GET_ADDRESS_STATE(F4,true,false) -> UNDEFINED | R4: =GOOGLEMAPS_GET_ADDRESS_POSTAL_CODE(F4,false,false) -> UNDEFINED | S4: =GOOGLEMAPS_GET_ADDRESS_COUNTRY(F4,true,false) -> Venezuela | T4: =IFERROR(GOOGLEMAPS_DISTANCE("2116 4th Ave, Seattle, WA, 98121", F4, "driving")+0,"Not Driveable") -> Not Driveable | U4: =iferror(GOOGLEMAPS_DURATION("2116 4th Ave, Seattle, WA, 98121", F4, "driving")+0,"Not Driveable") -> Not Driveable | V4: =GOOGLEMAPS_DISTANCE("2116 4th Ave, Seattle, WA, 98121", F4, "flying")+0 -> 3920.1623 | X4: =if(W4="YES","UNKNOWN","N/A") -> N/A | Z4: N/A
A5: 7 - Bucket List | B5: Faroe Islands | E5: 1 – Accessible – Freely | F5: Faroe Islands | G5: =HYPERLINK(CONCAT("https://www.google.com/maps/search/",F5),"Link") -> Link | H5: Nature | I5: =getCacheString(concat("GMPD|",F5)) -> {"address_components":[{"long_name":"Faroe Islands","types":["country","political"],"short_name":"FO"},{"short_name":"V3VQ+37","long_name":"V3VQ+37","types":["plus_code"]},{"long_name":"Skopun","types":["locality","political"],"short_name":"Skopun"},{"short_name":"Sandoy","long_name":"Sandoy","types":["administrative_area_level_1","political"]},{"types":["country","political"],"long_name":"Faroe Islands","short_name":"FO"},{"types":["latitude"],"long_name":61.89263500000001,"short_name":61.89263500000001},{"types":["longitude"],"long_name":-6.911805999999999,"short_name":-6.911805999999999}]} | J5: =GOOGLEMAPS_GET_ADDRESS_COMPONENTS_STRING(F5,false) -> [{"long_name":"Faroe Islands","types":["country","political"],"short_name":"FO"},{"short_name":"V3VQ+37","long_name":"V3VQ+37","types":["plus_code"]},{"long_name":"Skopun","types":["locality","political"],"short_name":"Skopun"},{"short_name":"Sandoy","long_name":"Sandoy","types":["administrative_area_level_1","political"]},{"types":["country","political"],"long_name":"Faroe Islands","short_name":"FO"},{"types":["latitude"],"long_name":61.89263500000001,"short_name":61.89263500000001},{"types":["longitude"],"long_name":-6.911805999999999,"short_name":-6.911805999999999},{"types":["debug_info","cache_load_result"],"long_name":"hit","short_name":"hit"}] | K5: =NOT(AND(NOT(_xlfn.ISFORMULA(P5)),AND(NOT(_xlfn.ISFORMULA(Q5)),AND(NOT(_xlfn.ISFORMULA(R5)),AND(NOT(_xlfn.ISFORMULA(S5)),AND(NOT(_xlfn.ISFORMULA(T5)),AND(NOT(_xlfn.ISFORMULA(U5)),AND(NOT(_xlfn.ISFORMULA(V5)),AND(NOT(_xlfn.ISFORMULA(N5)),NOT(_xlfn.ISFORMULA(O5))))))))))) -> FALSE | L5: =iferror(SEARCH(P5,F5),-1)>=0 -> FALSE | M5: TRUE | N5: 61.892635 | O5: -6.911806 | P5: Skopun | Q5: Sandoy | R5: UNDEFINED | S5: Faroe Islands | T5: Not Driveable | U5: Not Driveable | V5: 4076.06 | X5: =if(W5="YES","UNKNOWN","N/A") -> N/A | Z5: N/A
A6: 7 - Bucket List | B6: Isle of Skye | E6: 1 – Accessible – Freely | F6: Isle of Skye, Scotland | G6: =HYPERLINK(CONCAT("https://www.google.com/maps/search/",F6),"Link") -> Link | H6: Nature | I6: =getCacheString(concat("GMPD|",F6)) -> {"address_components":[{"long_name":"Skye","short_name":"Skye","types":["establishment","natural_feature"]},{"short_name":"Highland Council","types":["administrative_area_level_2","political"],"long_name":"Highland Council"},{"short_name":"Scotland","types":["administrative_area_level_1","political"],"long_name":"Scotland"},{"types":["country","political"],"long_name":"United Kingdom","short_name":"GB"},{"types":["plus_code"],"long_name":"7QFM+FQ","short_name":"7QFM+FQ"},{"types":["locality","political"],"long_name":"Sligachan","short_name":"Sligachan"},{"short_name":"Isle of Skye","long_name":"Isle of Skye","types":["postal_town"]},{"long_name":"Highland Council","short_name":"Highland Council","types":["administrative_area_level_2","political"]},{"long_name":"Scotland","short_name":"Scotland","types":["administrative_area_level_1","political"]},{"long_name":"United Kingdom","short_name":"GB","types":["country","political"]},{"long_name":"IV47 8SW","short_name":"IV47 8SW","types":["postal_code"]},{"types":["latitude"],"long_name":57.2736278,"short_name":57.2736278},{"types":["longitude"],"long_name":-6.2155022,"short_name":-6.2155022}],"distance_from":{"mi":{"flying":{"2116 4th Ave, Seattle, WA, 98121":4322.158773161669},"driving":{"2116 4th Ave, Seattle, WA, 98121":"GOOGLE_MAPS_ERROR_CACHED - No route found!"}}},"duration_from":{"days":{"driving":{"2116 4th Ave, Seattle, WA, 98121":"GOOGLE_MAPS_ERROR_CACHED - No route found!"}}}} | J6: =GOOGLEMAPS_GET_ADDRESS_COMPONENTS_STRING(F6,false) -> [{"long_name":"Skye","short_name":"Skye","types":["establishment","natural_feature"]},{"short_name":"Highland Council","types":["administrative_area_level_2","political"],"long_name":"Highland Council"},{"short_name":"Scotland","types":["administrative_area_level_1","political"],"long_name":"Scotland"},{"types":["country","political"],"long_name":"United Kingdom","short_name":"GB"},{"types":["plus_code"],"long_name":"7QFM+FQ","short_name":"7QFM+FQ"},{"types":["locality","political"],"long_name":"Sligachan","short_name":"Sligachan"},{"short_name":"Isle of Skye","long_name":"Isle of Skye","types":["postal_town"]},{"long_name":"Highland Council","short_name":"Highland Council","types":["administrative_area_level_2","political"]},{"long_name":"Scotland","short_name":"Scotland","types":["administrative_area_level_1","political"]},{"long_name":"United Kingdom","short_name":"GB","types":["country","political"]},{"long_name":"IV47 8SW","short_name":"IV47 8SW","types":["postal_code"]},{"types":["latitude"],"long_name":57.2736278,"short_name":57.2736278},{"types":["longitude"],"long_name":-6.2155022,"short_name":-6.2155022},{"types":["debug_info","cache_load_result"],"long_name":"hit","short_name":"hit"}] | K6: =NOT(AND(NOT(_xlfn.ISFORMULA(P6)),AND(NOT(_xlfn.ISFORMULA(Q6)),AND(NOT(_xlfn.ISFORMULA(R6)),AND(NOT(_xlfn.ISFORMULA(S6)),AND(NOT(_xlfn.ISFORMULA(T6)),AND(NOT(_xlfn.ISFORMULA(U6)),AND(NOT(_xlfn.ISFORMULA(V6)))))))))) -> TRUE | L6: =iferror(SEARCH(P6,F6),-1)>=0 -> FALSE | M6: TRUE | N6: =GOOGLEMAPS_GET_ADDRESS_LATITUDE(F6,true) -> 57.273628 | O6: =GOOGLEMAPS_GET_ADDRESS_LONGITUDE(F6,true) -> -6.2155022 | P6: =GOOGLEMAPS_GET_ADDRESS_CITY(F6,true,false) -> Sligachan | Q6: =GOOGLEMAPS_GET_ADDRESS_STATE(F6,true,false) -> Scotland | R6: =GOOGLEMAPS_GET_ADDRESS_POSTAL_CODE(F6,false,false) -> IV47 8SW | S6: =GOOGLEMAPS_GET_ADDRESS_COUNTRY(F6,true,false) -> United Kingdom | T6: =IFERROR(GOOGLEMAPS_DISTANCE("2116 4th Ave, Seattle, WA, 98121", F6, "driving")+0,"Not Driveable") -> Not Driveable | U6: =iferror(GOOGLEMAPS_DURATION("2116 4th Ave, Seattle, WA, 98121", F6, "driving")+0,"Not Driveable") -> Not Driveable | V6: =GOOGLEMAPS_DISTANCE("2116 4th Ave, Seattle, WA, 98121", F6, "flying")+0 -> 4322.1588 | X6: =if(W6="YES","UNKNOWN","N/A") -> N/A | Z6: N/A
A7: 7 - Bucket List | B7: Wistman's Wood | E7: 1 – Accessible – Freely | F7: Two Bridges, Princetown, United Kingdom | G7: =HYPERLINK(CONCAT("https://www.google.com/maps/search/",F7),"Link") -> Link | H7: Nature | I7: =getCacheString(concat("GMPD|",F7)) -> {"address_components":[{"long_name":"Princetown","short_name":"Princetown","types":["locality","political"]},{"long_name":"Yelverton","types":["postal_town"],"short_name":"Yelverton"},{"short_name":"Devon","types":["administrative_area_level_2","political"],"long_name":"Devon"},{"long_name":"England","types":["administrative_area_level_1","political"],"short_name":"England"},{"long_name":"United Kingdom","short_name":"GB","types":["country","political"]},{"short_name":"PL20","types":["postal_code","postal_code_prefix"],"long_name":"PL20"},{"long_name":"Railway Inn","types":["premise"],"short_name":"Railway Inn"},{"types":["route"],"long_name":"Two Bridges Road","short_name":"Two Bridges Rd"},{"short_name":"Princetown","long_name":"Princetown","types":["locality","political"]},{"long_name":"Yelverton","types":["postal_town"],"short_name":"Yelverton"},{"long_name":"Devon","short_name":"Devon","types":["administrative_area_level_2","political"]},{"long_name":"England","short_name":"England","types":["administrative_area_level_1","political"]},{"long_name":"United Kingdom","short_name":"GB","types":["country","political"]},{"long_name":"PL20 6QT","short_name":"PL20 6QT","types":["postal_code"]},{"types":["latitude"],"long_name":50.54412920000001,"short_name":50.54412920000001},{"types":["longitude"],"long_name":-3.9905352,"short_name":-3.9905352}]} | J7: =GOOGLEMAPS_GET_ADDRESS_COMPONENTS_STRING(F7,false) -> [{"long_name":"Princetown","short_name":"Princetown","types":["locality","political"]},{"long_name":"Yelverton","types":["postal_town"],"short_name":"Yelverton"},{"short_name":"Devon","types":["administrative_area_level_2","political"],"long_name":"Devon"},{"long_name":"England","types":["administrative_area_level_1","political"],"short_name":"England"},{"long_name":"United Kingdom","short_name":"GB","types":["country","political"]},{"short_name":"PL20","types":["postal_code","postal_code_prefix"],"long_name":"PL20"},{"long_name":"Railway Inn","types":["premise"],"short_name":"Railway Inn"},{"types":["route"],"long_name":"Two Bridges Road","short_name":"Two Bridges Rd"},{"short_name":"Princetown","long_name":"Princetown","types":["locality","political"]},{"long_name":"Yelverton","types":["postal_town"],"short_name":"Yelverton"},{"long_name":"Devon","short_name":"Devon","types":["administrative_area_level_2","political"]},{"long_name":"England","short_name":"England","types":["administrative_area_level_1","political"]},{"long_name":"United Kingdom","short_name":"GB","types":["country","political"]},{"long_name":"PL20 6QT","short_name":"PL20 6QT","types":["postal_code"]},{"types":["latitude"],"long_name":50.54412920000001,"short_name":50.54412920000001},{"types":["longitude"],"long_name":-3.9905352,"short_name":-3.9905352},{"types":["debug_info","cache_load_result"],"long_name":"hit","short_name":"hit"}] | K7: =NOT(AND(NOT(_xlfn.ISFORMULA(P7)),AND(NOT(_xlfn.ISFORMULA(Q7)),AND(NOT(_xlfn.ISFORMULA(R7)),AND(NOT(_xlfn.ISFORMULA(S7)),AND(NOT(_xlfn.ISFORMULA(T7)),AND(NOT(_xlfn.ISFORMULA(U7)),AND(NOT(_xlfn.ISFORMULA(V7)),AND(NOT(_xlfn.ISFORMULA(N7)),NOT(_xlfn.ISFORMULA(O7))))))))))) -> FALSE | L7: =iferror(SEARCH(P7,F7),-1)>=0 -> TRUE | M7: TRUE | N7: 50.545768 | O7: -3.9883076 | P7: Princetown | Q7: England | R7: PL20 | S7: United Kingdom | T7: Not Driveable | U7: Not Driveable | V7: 4731.31 | X7: =if(W7="YES","UNKNOWN","N/A") -> N/A | Z7: N/A
A8: 7 - Bucket List | B8: The Tumen River | C8: The Tumen River is a gateway between China, North Korea and Russia | D8: The Tumen River makes up part of the boundary between China, North Korea and Russia. Due to the fact that many North Koreans have been caught trying to enter China through the river’s shallow waters, the Tumen River is tightly guarded by the three countries. | E8: 7 – Inaccessible – Government Property / Ban | F8: The Tumen River | G8: =HYPERLINK(CONCAT("https://www.google.com/maps/search/",F8),"Link") -> Link | H8: Nature | I8: =getCacheString(concat("GMPD|",F8)) -> {"address_components":[{"long_name":"Tumen River","types":["establishment","natural_feature"],"short_name":"Tumen River"},{"long_name":"8QJFFHWF+H4","short_name":"8QJFFHWF+H4","types":["plus_code"]},{"types":["latitude"],"long_name":42.49638202036756,"short_name":42.49638202036756},{"types":["longitude"],"long_name":129.5727514781101,"short_name":129.5727514781101}]} | J8: =GOOGLEMAPS_GET_ADDRESS_COMPONENTS_STRING(F8,false) -> [{"long_name":"Tumen River","types":["establishment","natural_feature"],"short_name":"Tumen River"},{"long_name":"8QJFFHWF+H4","short_name":"8QJFFHWF+H4","types":["plus_code"]},{"types":["latitude"],"long_name":42.49638202036756,"short_name":42.49638202036756},{"types":["longitude"],"long_name":129.5727514781101,"short_name":129.5727514781101},{"types":["debug_info","cache_load_result"],"long_name":"hit","short_name":"hit"}] | K8: =NOT(AND(NOT(_xlfn.ISFORMULA(P8)),AND(NOT(_xlfn.ISFORMULA(Q8)),AND(NOT(_xlfn.ISFORMULA(R8)),AND(NOT(_xlfn.ISFORMULA(S8)),AND(NOT(_xlfn.ISFORMULA(T8)),AND(NOT(_xlfn.ISFORMULA(U8)),AND(NOT(_xlfn.ISFORMULA(V8)),AND(NOT(_xlfn.ISFORMULA(N8)),NOT(_xlfn.ISFORMULA(O8))))))))))) -> FALSE | L8: =iferror(SEARCH(P8,F8),-1)>=0 -> FALSE | M8: TRUE | N8: 42.496382 | O8: 129.57275 | P8: UNDEFINED | Q8: UNDEFINED | R8: UNDEFINED | S8: UNDEFINED | T8: Not Driveable | U8: Not Driveable | V8: 4825.36 | X8: =if(W8="YES","UNKNOWN","N/A") -> N/A | Z8: N/A | AB8: https://magazine.lensvid.com/article/fb/1318327108/mysterious-places-in-the-world-that-are-off-limits-to-everyone-and-why/
A9: 7 - Bucket List | B9: Ise Grand Shrine, Japan | C9: Only the Japanese Imperial family is allowed inside the Ise Grand Shrine | D9: Erected in 4 BCE, the Ise Grand Shrine is considered the birthplace of Shinto, Japan’s native belief system. The shrine is so sacred to the Japanese that it receives over six million visitors every year even though access to the site is extremely limited. While only members of the Imperial family are allowed inside the main shrine, the general public can roam the forest around the Ise Grand Shrine. | E9: 7 – Inaccessible – Government Property / Ban | F9: Ise Grand Shrine, Japan | G9: =HYPERLINK(CONCAT("https://www.google.com/maps/search/",F9),"Link") -> Link | H9: Religious Site | I9: =getCacheString(concat("GMPD|",F9)) -> {"address_components":[{"long_name":"1","short_name":"1","types":["premise"]},{"types":["political","sublocality","sublocality_level_2"],"short_name":"Ujitachichō","long_name":"Ujitachichō"},{"types":["locality","political"],"long_name":"Ise","short_name":"Ise"},{"types":["administrative_area_level_1","political"],"short_name":"Mie","long_name":"Mie"},{"long_name":"Japan","types":["country","political"],"short_name":"JP"},{"long_name":"516-0023","types":["postal_code"],"short_name":"516-0023"},{"long_name":"1","short_name":"1","types":["premise"]},{"long_name":"Ujitachichō","short_name":"Ujitachichō","types":["political","sublocality","sublocality_level_2"]},{"types":["locality","political"],"short_name":"Ise","long_name":"Ise"},{"long_name":"Mie","types":["administrative_area_level_1","political"],"short_name":"Mie"},{"long_name":"Japan","types":["country","political"],"short_name":"JP"},{"short_name":"516-0023","long_name":"516-0023","types":["postal_code"]},{"types":["latitude"],"long_name":34.4550038,"short_name":34.4550038},{"types":["longitude"],"long_name":136.7254738,"short_name":136.7254738}]} | J9: =GOOGLEMAPS_GET_ADDRESS_COMPONENTS_STRING(F9,false) -> [{"long_name":"1","short_name":"1","types":["premise"]},{"types":["political","sublocality","sublocality_level_2"],"short_name":"Ujitachichō","long_name":"Ujitachichō"},{"types":["locality","political"],"long_name":"Ise","short_name":"Ise"},{"types":["administrative_area_level_1","political"],"short_name":"Mie","long_name":"Mie"},{"long_name":"Japan","types":["country","political"],"short_name":"JP"},{"long_name":"516-0023","types":["postal_code"],"short_name":"516-0023"},{"long_name":"1","short_name":"1","types":["premise"]},{"long_name":"Ujitachichō","short_name":"Ujitachichō","types":["political","sublocality","sublocality_level_2"]},{"types":["locality","political"],"short_name":"Ise","long_name":"Ise"},{"long_name":"Mie","types":["administrative_area_level_1","political"],"short_name":"Mie"},{"long_name":"Japan","types":["country","political"],"short_name":"JP"},{"short_name":"516-0023","long_name":"516-0023","types":["postal_code"]},{"types":["latitude"],"long_name":34.4550038,"short_name":34.4550038},{"types":["longitude"],"long_name":136.7254738,"short_name":136.7254738},{"types":["debug_info","cache_load_result"],"long_name":"hit","short_name":"hit"}] | K9: =NOT(AND(NOT(_xlfn.ISFORMULA(P9)),AND(NOT(_xlfn.ISFORMULA(Q9)),AND(NOT(_xlfn.ISFORMULA(R9)),AND(NOT(_xlfn.ISFORMULA(S9)),AND(NOT(_xlfn.ISFORMULA(T9)),AND(NOT(_xlfn.ISFORMULA(U9)),AND(NOT(_xlfn.ISFORMULA(V9)),AND(NOT(_xlfn.ISFORMULA(N9)),NOT(_xlfn.ISFORMULA(O9))))))))))) -> FALSE | L9: =iferror(SEARCH(P9,F9),-1)>=0 -> TRUE | M9: TRUE | N9: 34.45501 | O9: 136.72579 | P9: Ise | Q9: Mie | R9: 516-0023 | S9: Japan | T9: Not Driveable | U9: Not Driveable | V9: 4960.38 | X9: =if(W9="YES","UNKNOWN","N/A") -> N/A | Z9: N/A | AB9: https://magazine.lensvid.com/article/fb/1318327108/mysterious-places-in-the-world-that-are-off-limits-to-everyone-and-why/
A10: 7 - Bucket List | B10: Paris Catacombs | C10: The majority of the Catacombs of Paris is off-limits to the public | D10: Originally built as a tunnel network to consolidate the French capital’s ancient mines, the Catacombs of Paris are underground ossuaries that hold the remains of over six million people. A small section of these tunnels is open to the general public, but the majority of the 170-mile-long maze is closed off to prevent visitors from getting lost. | E10: 3 – Accessible – Tour Guide Required | F10: Paris Catacombs | G10: =HYPERLINK(CONCAT("https://www.google.com/maps/search/",F10),"Link") -> Link | I10: =getCacheString(concat("GMPD|",F10)) -> {"address_components":[{"long_name":"1","types":["street_number"],"short_name":"1"},{"types":["route"],"short_name":"Av. du Colonel Henri Rol-Tanguy","long_name":"Avenue du Colonel Henri Rol-Tanguy"},{"long_name":"Paris","types":["locality","political"],"short_name":"Paris"},{"types":["administrative_area_level_2","political"],"short_name":"Paris","long_name":"Paris"},{"long_name":"Île-de-France","short_name":"IDF","types":["administrative_area_level_1","political"]},{"long_name":"France","types":["country","political"],"short_name":"FR"},{"short_name":"75014","types":["postal_code"],"long_name":"75014"},{"types":["street_number"],"long_name":"3","short_name":"3"},{"short_name":"Av. du Colonel Henri Rol-Tanguy","types":["route"],"long_name":"Avenue du Colonel Henri Rol-Tanguy"},{"short_name":"Paris","long_name":"Paris","types":["locality","political"]},{"short_name":"Paris","long_name":"Paris","types":["administrative_area_level_2","political"]},{"short_name":"IDF","types":["administrative_area_level_1","political"],"long_name":"Île-de-France"},{"long_name":"France","types":["country","political"],"short_name":"FR"},{"types":["postal_code"],"short_name":"75014","long_name":"75014"},{"types":["latitude"],"long_name":48.8338325,"short_name":48.8338325},{"types":["longitude"],"long_name":2.3324222,"short_name":2.3324222}]} | J10: =GOOGLEMAPS_GET_ADDRESS_COMPONENTS_STRING(F10,false) -> [{"long_name":"1","types":["street_number"],"short_name":"1"},{"types":["route"],"short_name":"Av. du Colonel Henri Rol-Tanguy","long_name":"Avenue du Colonel Henri Rol-Tanguy"},{"long_name":"Paris","types":["locality","political"],"short_name":"Paris"},{"types":["administrative_area_level_2","political"],"short_name":"Paris","long_name":"Paris"},{"long_name":"Île-de-France","short_name":"IDF","types":["administrative_area_level_1","political"]},{"long_name":"France","types":["country","political"],"short_name":"FR"},{"short_name":"75014","types":["postal_code"],"long_name":"75014"},{"types":["street_number"],"long_name":"3","short_name":"3"},{"short_name":"Av. du Colonel Henri Rol-Tanguy","types":["route"],"long_name":"Avenue du Colonel Henri Rol-Tanguy"},{"short_name":"Paris","long_name":"Paris","types":["locality","political"]},{"short_name":"Paris","long_name":"Paris","types":["administrative_area_level_2","political"]},{"short_name":"IDF","types":["administrative_area_level_1","political"],"long_name":"Île-de-France"},{"long_name":"France","types":["country","political"],"short_name":"FR"},{"types":["postal_code"],"short_name":"75014","long_name":"75014"},{"types":["latitude"],"long_name":48.8338325,"short_name":48.8338325},{"types":["longitude"],"long_name":2.3324222,"short_name":2.3324222},{"types":["debug_info","cache_load_result"],"long_name":"hit","short_name":"hit"}] | K10: =NOT(AND(NOT(_xlfn.ISFORMULA(P10)),AND(NOT(_xlfn.ISFORMULA(Q10)),AND(NOT(_xlfn.ISFORMULA(R10)),AND(NOT(_xlfn.ISFORMULA(S10)),AND(NOT(_xlfn.ISFORMULA(T10)),AND(NOT(_xlfn.ISFORMULA(U10)),AND(NOT(_xlfn.ISFORMULA(V10)),AND(NOT(_xlfn.ISFORMULA(N10)),NOT(_xlfn.ISFORMULA(O10))))))))))) -> FALSE | L10: =iferror(SEARCH(P10,F10),-1)>=0 -> TRUE | M10: TRUE | N10: 48.833832 | O10: 2.3324222 | P10: Paris | Q10: Île-de-France | R10: 75014 | S10: France | T10: Not Driveable | U10: Not Driveable | V10: 4997.29 | X10: =if(W10="YES","UNKNOWN","N/A") -> N/A | Z10: 43120 | AB10: https://magazine.lensvid.com/article/fb/1318327108/mysterious-places-in-the-world-that-are-off-limits-to-everyone-and-why/
A11: 7 - Bucket List | B11: Svalbard | C11: One of the world’s northernmost inhabited areas with the world's northernmost brewery | E11: 1 – Accessible – Freely | F11: Svalbard, Norway | G11: =HYPERLINK(CONCAT("https://www.google.com/maps/search/",F11),"Link") -> Link | H11: Nature | I11: =getCacheString(concat("GMPD|",F11)) -> {"distance_from":{"mi":{"driving":{"2116 4th Ave, Seattle, WA, 98121":"GOOGLE_MAPS_ERROR_CACHED - No route found!"},"flying":{"2116 4th Ave, Seattle, WA, 98121":3628.238284017051}}},"address_components":[{"types":["administrative_area_level_1","political"],"short_name":"Svalbard","long_name":"Svalbard"},{"types":["country","political"],"long_name":"Svalbard and Jan Mayen","short_name":"SJ"},{"short_name":"","long_name":"Ян-Майен, Шпицберген, Улица Олёшивоская","types":[]},{"types":["country","political"],"long_name":"Svalbard and Jan Mayen","short_name":"SJ"},{"types":["administrative_area_level_1","political"],"short_name":"Svalbard","long_name":"Svalbard"},{"types":["postal_code"],"long_name":"9170","short_name":"9170"},{"types":["latitude"],"long_name":77.8749725,"short_name":77.8749725},{"types":["longitude"],"long_name":20.9751822,"short_name":20.9751822}],"duration_from":{"days":{"driving":{"2116 4th Ave, Seattle, WA, 98121":"GOOGLE_MAPS_ERROR_CACHED - No route found!"}}}} | J11: =GOOGLEMAPS_GET_ADDRESS_COMPONENTS_STRING(F11,false) -> [{"types":["administrative_area_level_1","political"],"short_name":"Svalbard","long_name":"Svalbard"},{"types":["country","political"],"long_name":"Svalbard and Jan Mayen","short_name":"SJ"},{"short_name":"","long_name":"Ян-Майен, Шпицберген, Улица Олёшивоская","types":[]},{"types":["country","political"],"long_name":"Svalbard and Jan Mayen","short_name":"SJ"},{"types":["administrative_area_level_1","political"],"short_name":"Svalbard","long_name":"Svalbard"},{"types":["postal_code"],"long_name":"9170","short_name":"9170"},{"types":["latitude"],"long_name":77.8749725,"short_name":77.8749725},{"types":["longitude"],"long_name":20.9751822,"short_name":20.9751822},{"types":["debug_info","cache_load_result"],"long_name":"hit","short_name":"hit"}] | K11: =NOT(AND(NOT(_xlfn.ISFORMULA(P11)),AND(NOT(_xlfn.ISFORMULA(Q11)),AND(NOT(_xlfn.ISFORMULA(R11)),AND(NOT(_xlfn.ISFORMULA(S11)),AND(NOT(_xlfn.ISFORMULA(T11)),AND(NOT(_xlfn.ISFORMULA(U11)),AND(NOT(_xlfn.ISFORMULA(V11)))))))))) -> TRUE | L11: =iferror(SEARCH(P11,F11),-1)>=0 -> FALSE | M11: TRUE | N11: =GOOGLEMAPS_GET_ADDRESS_LATITUDE(F11,true) -> 77.874972 | O11: =GOOGLEMAPS_GET_ADDRESS_LONGITUDE(F11,true) -> 20.975182 | P11: =GOOGLEMAPS_GET_ADDRESS_CITY(F11,true,false) -> Longyearbyen | Q11: =GOOGLEMAPS_GET_ADDRESS_STATE(F11,true,false) -> Svalbard | R11: =GOOGLEMAPS_GET_ADDRESS_POSTAL_CODE(F11,false,false) -> 9170 | S11: =GOOGLEMAPS_GET_ADDRESS_COUNTRY(F11,true,false) -> Svalbard and Jan Mayen | T11: =IFERROR(GOOGLEMAPS_DISTANCE("2116 4th Ave, Seattle, WA, 98121", F11, "driving")+0,"Not Driveable") -> Not Driveable | U11: =iferror(GOOGLEMAPS_DURATION("2116 4th Ave, Seattle, WA, 98121", F11, "driving")+0,"Not Driveable") -> Not Driveable | V11: =GOOGLEMAPS_DISTANCE("2116 4th Ave, Seattle, WA, 98121", F11, "flying")+0 -> 3628.2383 | X11: =if(W11="YES","UNKNOWN","N/A") -> N/A | Z11: N/A | AA11: Have a beer at the northernmost Brewery and experience remote nature | AE11: Northernmost brewery in the world
A12: 7 - Bucket List | B12: Hotel Bareiss | E12: 1 – Accessible – Freely | F12: Hotel Bareiss, Germany | G12: =HYPERLINK(CONCAT("https://www.google.com/maps/search/",F12),"Link") -> Link | H12: Destination Retreat / Getaway | I12: =getCacheString(concat("GMPD|",F12)) -> {"address_components":[{"short_name":"1","long_name":"1","types":["street_number"]},{"short_name":"Hermine-Bareiss-Weg","long_name":"Hermine-Bareiss-Weg","types":["route"]},{"long_name":"Mitteltal","types":["political","sublocality","sublocality_level_1"],"short_name":"Mitteltal"},{"types":["locality","political"],"long_name":"Baiersbronn","short_name":"Baiersbronn"},{"types":["administrative_area_level_3","political"],"long_name":"Landkreis Freudenstadt","short_name":"FDS"},{"short_name":"KA","long_name":"Karlsruhe","types":["administrative_area_level_2","political"]},{"short_name":"BW","long_name":"Baden-Württemberg","types":["administrative_area_level_1","political"]},{"long_name":"Germany","types":["country","political"],"short_name":"DE"},{"types":["postal_code"],"short_name":"72270","long_name":"72270"},{"long_name":"1","types":["street_number"],"short_name":"1"},{"types":["route"],"long_name":"Hermine-Bareiss-Weg","short_name":"Hermine-Bareiss-Weg"},{"short_name":"Mitteltal","types":["political","sublocality","sublocality_level_1"],"long_name":"Mitteltal"},{"long_name":"Baiersbronn","types":["locality","political"],"short_name":"Baiersbronn"},{"types":["administrative_area_level_3","political"],"long_name":"Landkreis Freudenstadt","short_name":"FDS"},{"long_name":"Karlsruhe","types":["administrative_area_level_2","political"],"short_name":"KA"},{"long_name":"Baden-Württemberg","types":["administrative_area_level_1","political"],"short_name":"BW"},{"short_name":"DE","long_name":"Germany","types":["country","political"]},{"types":["postal_code"],"long_name":"72270","short_name":"72270"},{"types":["latitude"],"long_name":48.5203306,"short_name":48.5203306},{"types":["longitude"],"long_name":8.32685,"short_name":8.32685}]} | J12: =GOOGLEMAPS_GET_ADDRESS_COMPONENTS_STRING(F12,false) -> [{"short_name":"1","long_name":"1","types":["street_number"]},{"short_name":"Hermine-Bareiss-Weg","long_name":"Hermine-Bareiss-Weg","types":["route"]},{"long_name":"Mitteltal","types":["political","sublocality","sublocality_level_1"],"short_name":"Mitteltal"},{"types":["locality","political"],"long_name":"Baiersbronn","short_name":"Baiersbronn"},{"types":["administrative_area_level_3","political"],"long_name":"Landkreis Freudenstadt","short_name":"FDS"},{"short_name":"KA","long_name":"Karlsruhe","types":["administrative_area_level_2","political"]},{"short_name":"BW","long_name":"Baden-Württemberg","types":["administrative_area_level_1","political"]},{"long_name":"Germany","types":["country","political"],"short_name":"DE"},{"types":["postal_code"],"short_name":"72270","long_name":"72270"},{"long_name":"1","types":["street_number"],"short_name":"1"},{"types":["route"],"long_name":"Hermine-Bareiss-Weg","short_name":"Hermine-Bareiss-Weg"},{"short_name":"Mitteltal","types":["political","sublocality","sublocality_level_1"],"long_name":"Mitteltal"},{"long_name":"Baiersbronn","types":["locality","political"],"short_name":"Baiersbronn"},{"types":["administrative_area_level_3","political"],"long_name":"Landkreis Freudenstadt","short_name":"FDS"},{"long_name":"Karlsruhe","types":["administrative_area_level_2","political"],"short_name":"KA"},{"long_name":"Baden-Württemberg","types":["administrative_area_level_1","political"],"short_name":"BW"},{"short_name":"DE","long_name":"Germany","types":["country","political"]},{"types":["postal_code"],"long_name":"72270","short_name":"72270"},{"types":["latitude"],"long_name":48.5203306,"short_name":48.5203306},{"types":["longitude"],"long_name":8.32685,"short_name":8.32685},{"types":["debug_info","cache_load_result"],"long_name":"hit","short_name":"hit"}] | K12: =NOT(AND(NOT(_xlfn.ISFORMULA(P12)),AND(NOT(_xlfn.ISFORMULA(Q12)),AND(NOT(_xlfn.ISFORMULA(R12)),AND(NOT(_xlfn.ISFORMULA(S12)),AND(NOT(_xlfn.ISFORMULA(T12)),AND(NOT(_xlfn.ISFORMULA(U12)),AND(NOT(_xlfn.ISFORMULA(V12)),AND(NOT(_xlfn.ISFORMULA(N12)),NOT(_xlfn.ISFORMULA(O12))))))))))) -> FALSE | L12: =iferror(SEARCH(P12,F12),-1)>=0 -> FALSE | M12: TRUE | N12: 48.520331 | O12: 8.32685 | P12: Baiersbronn | Q12: Baden-Württemberg | R12: 72270 | S12: Germany | T12: Not Driveable | U12: Not Driveable | V12: 5167.37 | X12: =if(W12="YES","UNKNOWN","N/A") -> N/A | Z12: N/A | AB12: https://www.bareiss.com/en/ | AF12: Resort and Spa in the Black Forrest
A13: 7 - Bucket List | B13: Chernobyl Exclusion Zone | C13: Exclusion zone around Chernobyl | E13: 8 – Inaccessible – Military Action / Dispute / Unrest | F13: Chernobyl Exclusion Zone, Belarus | G13: =HYPERLINK(CONCAT("https://www.google.com/maps/search/",F13),"Link") -> Link | H13: Ghost Town | I13: =getCacheString(concat("GMPD|",F13)) -> {"address_components":[{"long_name":"Belarus","short_name":"BY","types":["country","political"]},{"long_name":"PX53+W9","short_name":"PX53+W9","types":["plus_code"]},{"short_name":"Golomberg","long_name":"Golomberg","types":["locality","political"]},{"short_name":"Pukhavichy District","types":["administrative_area_level_2","political"],"long_name":"Pukhavichy District"},{"short_name":"Minsk Region","long_name":"Minsk Region","types":["administrative_area_level_1","political"]},{"long_name":"Belarus","short_name":"BY","types":["country","political"]},{"types":["latitude"],"long_name":53.709807,"short_name":53.709807},{"types":["longitude"],"long_name":27.953389,"short_name":27.953389}],"duration_from":{"days":{"driving":{"2116 4th Ave, Seattle, WA, 98121":"GOOGLE_MAPS_ERROR_CACHED - No route found!"}}},"distance_from":{"mi":{"driving":{"2116 4th Ave, Seattle, WA, 98121":"GOOGLE_MAPS_ERROR_CACHED - No route found!"},"flying":{"2116 4th Ave, Seattle, WA, 98121":5223.046714802342}}}} | J13: =GOOGLEMAPS_GET_ADDRESS_COMPONENTS_STRING(F13,false) -> [{"long_name":"Belarus","short_name":"BY","types":["country","political"]},{"long_name":"PX53+W9","short_name":"PX53+W9","types":["plus_code"]},{"short_name":"Golomberg","long_name":"Golomberg","types":["locality","political"]},{"short_name":"Pukhavichy District","types":["administrative_area_level_2","political"],"long_name":"Pukhavichy District"},{"short_name":"Minsk Region","long_name":"Minsk Region","types":["administrative_area_level_1","political"]},{"long_name":"Belarus","short_name":"BY","types":["country","political"]},{"types":["latitude"],"long_name":53.709807,"short_name":53.709807},{"types":["longitude"],"long_name":27.953389,"short_name":27.953389},{"types":["debug_info","cache_load_result"],"long_name":"hit","short_name":"hit"}] | K13: =NOT(AND(NOT(_xlfn.ISFORMULA(P13)),AND(NOT(_xlfn.ISFORMULA(Q13)),AND(NOT(_xlfn.ISFORMULA(R13)),AND(NOT(_xlfn.ISFORMULA(S13)),AND(NOT(_xlfn.ISFORMULA(T13)),AND(NOT(_xlfn.ISFORMULA(U13)),AND(NOT(_xlfn.ISFORMULA(V13)))))))))) -> TRUE | L13: =iferror(SEARCH(P13,F13),-1)>=0 -> FALSE | M13: TRUE | N13: =GOOGLEMAPS_GET_ADDRESS_LATITUDE(F13,true) -> 53.709807 | O13: =GOOGLEMAPS_GET_ADDRESS_LONGITUDE(F13,true) -> 27.953389 | P13: =GOOGLEMAPS_GET_ADDRESS_CITY(F13,true,false) -> Golomberg | Q13: =GOOGLEMAPS_GET_ADDRESS_STATE(F13,true,false) -> Minsk Region | R13: =GOOGLEMAPS_GET_ADDRESS_POSTAL_CODE(F13,false,false) -> UNDEFINED | S13: =GOOGLEMAPS_GET_ADDRESS_COUNTRY(F13,true,false) -> Belarus | T13: =IFERROR(GOOGLEMAPS_DISTANCE("2116 4th Ave, Seattle, WA, 98121", F13, "driving")+0,"Not Driveable") -> Not Driveable | U13: =iferror(GOOGLEMAPS_DURATION("2116 4th Ave, Seattle, WA, 98121", F13, "driving")+0,"Not Driveable") -> Not Driveable | V13: =GOOGLEMAPS_DISTANCE("2116 4th Ave, Seattle, WA, 98121", F13, "flying")+0 -> 5223.0467 | X13: =if(W13="YES","UNKNOWN","N/A") -> N/A | Z13: N/A | AC13: https://www.youtube.com/watch?v=Qk_gx3CmACY | AD13: https://www.youtube.com/watch?v=sSIlZcEWyqg
A14: 7 - Bucket List | B14: Alsace, France | C14: Alsace is one of the most beautiful regions in France. It is known for its Christmas markets, its castles, its wine road and its proximity to Germany. It is also known for its high-quality gastronomy, especially its sauerkraut, its Flammekueche, and its white wines. | E14: 1 – Accessible – Freely | F14: Alsace, France | G14: =HYPERLINK(CONCAT("https://www.google.com/maps/search/",F14),"Link") -> Link | H14: World Class Cities and Lands | I14: =getCacheString(concat("GMPD|",F14)) -> {"address_components":[{"long_name":"Alsace","short_name":"Alsace","types":["colloquial_area","political"]},{"short_name":"Grand Est","types":["administrative_area_level_1","political"],"long_name":"Grand Est"},{"long_name":"France","types":["country","political"],"short_name":"FR"},{"long_name":"21","types":["street_number"],"short_name":"21"},{"long_name":"Rue des Boutons d'Or","short_name":"Rue des Boutons d'Or","types":["route"]},{"long_name":"Dambach-la-Ville","short_name":"Dambach-la-Ville","types":["locality","political"]},{"types":["administrative_area_level_2","political"],"short_name":"Bas-Rhin","long_name":"Bas-Rhin"},{"long_name":"Grand Est","short_name":"Grand Est","types":["administrative_area_level_1","political"]},{"types":["country","political"],"short_name":"FR","long_name":"France"},{"long_name":"67650","short_name":"67650","types":["postal_code"]},{"types":["latitude"],"long_name":48.3181795,"short_name":48.3181795},{"types":["longitude"],"long_name":7.441624099999999,"short_name":7.441624099999999}],"duration_from":{"days":{"driving":{"2116 4th Ave, Seattle, WA, 98121":"GOOGLE_MAPS_ERROR_CACHED - No route found!"}}},"distance_from":{"mi":{"flying":{"2116 4th Ave, Seattle, WA, 98121":5157.514260504307},"driving":{"2116 4th Ave, Seattle, WA, 98121":"GOOGLE_MAPS_ERROR_CACHED - No route found!"}}}} | J14: =GOOGLEMAPS_GET_ADDRESS_COMPONENTS_STRING(F14,false) -> [{"long_name":"Alsace","short_name":"Alsace","types":["colloquial_area","political"]},{"short_name":"Grand Est","types":["administrative_area_level_1","political"],"long_name":"Grand Est"},{"long_name":"France","types":["country","political"],"short_name":"FR"},{"long_name":"21","types":["street_number"],"short_name":"21"},{"long_name":"Rue des Boutons d'Or","short_name":"Rue des Boutons d'Or","types":["route"]},{"long_name":"Dambach-la-Ville","short_name":"Dambach-la-Ville","types":["locality","political"]},{"types":["administrative_area_level_2","political"],"short_name":"Bas-Rhin","long_name":"Bas-Rhin"},{"long_name":"Grand Est","short_name":"Grand Est","types":["administrative_area_level_1","political"]},{"types":["country","political"],"short_name":"FR","long_name":"France"},{"long_name":"67650","short_name":"67650","types":["postal_code"]},{"types":["latitude"],"long_name":48.3181795,"short_name":48.3181795},{"types":["longitude"],"long_name":7.441624099999999,"short_name":7.441624099999999},{"types":["debug_info","cache_load_result"],"long_name":"hit","short_name":"hit"}] | K14: =NOT(AND(NOT(_xlfn.ISFORMULA(P14)),AND(NOT(_xlfn.ISFORMULA(Q14)),AND(NOT(_xlfn.ISFORMULA(R14)),AND(NOT(_xlfn.ISFORMULA(S14)),AND(NOT(_xlfn.ISFORMULA(T14)),AND(NOT(_xlfn.ISFORMULA(U14)),AND(NOT(_xlfn.ISFORMULA(V14)))))))))) -> TRUE | L14: =iferror(SEARCH(P14,F14),-1)>=0 -> FALSE | M14: TRUE | N14: =GOOGLEMAPS_GET_ADDRESS_LATITUDE(F14,true) -> 48.318179 | O14: =GOOGLEMAPS_GET_ADDRESS_LONGITUDE(F14,true) -> 7.4416241 | P14: =GOOGLEMAPS_GET_ADDRESS_CITY(F14,true,false) -> Dambach-la-Ville | Q14: =GOOGLEMAPS_GET_ADDRESS_STATE(F14,true,false) -> Grand Est | R14: =GOOGLEMAPS_GET_ADDRESS_POSTAL_CODE(F14,false,false) -> 67650 | S14: =GOOGLEMAPS_GET_ADDRESS_COUNTRY(F14,true,false) -> France | T14: =IFERROR(GOOGLEMAPS_DISTANCE("2116 4th Ave, Seattle, WA, 98121", F14, "driving")+0,"Not Driveable") -> Not Driveable | U14: =iferror(GOOGLEMAPS_DURATION("2116 4th Ave, Seattle, WA, 98121", F14, "driving")+0,"Not Driveable") -> Not Driveable | V14: =GOOGLEMAPS_DISTANCE("2116 4th Ave, Seattle, WA, 98121", F14, "flying")+0 -> 5157.5143 | X14: =if(W14="YES","UNKNOWN","N/A") -> N/A | Z14: N/A
A15: 7 - Bucket List | B15: Korean Demilitarized Zone, Korean Peninsula | C15: The Korean Demilitarized Zone is so deadly for humans that it became an involuntary nature reserve | D15: The Korean Demilitarized Zone is a border barrier between North and South Korea. Since it is highly militarized on both sides to prevent people from crossing the border, the DMZ region sees very little human activity, accidentally making it a safe haven for wild animals and migratory birds. | E15: 8 – Inaccessible – Military Action / Dispute / Unrest | F15: Korean Demilitarized Zone, Korean Peninsula | G15: =HYPERLINK(CONCAT("https://www.google.com/maps/search/",F15),"Link") -> Link | I15: =getCacheString(concat("GMPD|",F15)) -> {"address_components":[{"types":["country","political"],"short_name":"KR","long_name":"South Korea"},{"types":["premise"],"long_name":"808-3","short_name":"808-3"},{"long_name":"Samgong-ri","types":["political","sublocality","sublocality_level_3"],"short_name":"Samgong-ri"},{"short_name":"Seolcheon-myeon","long_name":"Seolcheon-myeon","types":["political","sublocality","sublocality_level_2"]},{"short_name":"Muju","long_name":"Muju","types":["locality","political"]},{"long_name":"Jeonbuk State","types":["administrative_area_level_1","political"],"short_name":"Jeonbuk State"},{"short_name":"KR","long_name":"South Korea","types":["country","political"]},{"types":["postal_code"],"long_name":"55557","short_name":"55557"},{"types":["latitude"],"long_name":35.907757,"short_name":35.907757},{"types":["longitude"],"long_name":127.766922,"short_name":127.766922}],"distance_from":{"mi":{"flying":{"2116 4th Ave, Seattle, WA, 98121":5228.674487678179},"driving":{"2116 4th Ave, Seattle, WA, 98121":"GOOGLE_MAPS_ERROR_CACHED - No route found!"}}},"duration_from":{"days":{"driving":{"2116 4th Ave, Seattle, WA, 98121":"GOOGLE_MAPS_ERROR_CACHED - No route found!"}}}} | J15: =GOOGLEMAPS_GET_ADDRESS_COMPONENTS_STRING(F15,false) -> [{"types":["country","political"],"short_name":"KR","long_name":"South Korea"},{"types":["premise"],"long_name":"808-3","short_name":"808-3"},{"long_name":"Samgong-ri","types":["political","sublocality","sublocality_level_3"],"short_name":"Samgong-ri"},{"short_name":"Seolcheon-myeon","long_name":"Seolcheon-myeon","types":["political","sublocality","sublocality_level_2"]},{"short_name":"Muju","long_name":"Muju","types":["locality","political"]},{"long_name":"Jeonbuk State","types":["administrative_area_level_1","political"],"short_name":"Jeonbuk State"},{"short_name":"KR","long_name":"South Korea","types":["country","political"]},{"types":["postal_code"],"long_name":"55557","short_name":"55557"},{"types":["latitude"],"long_name":35.907757,"short_name":35.907757},{"types":["longitude"],"long_name":127.766922,"short_name":127.766922},{"types":["debug_info","cache_load_result"],"long_name":"hit","short_name":"hit"}] | K15: =NOT(AND(NOT(_xlfn.ISFORMULA(P15)),AND(NOT(_xlfn.ISFORMULA(Q15)),AND(NOT(_xlfn.ISFORMULA(R15)),AND(NOT(_xlfn.ISFORMULA(S15)),AND(NOT(_xlfn.ISFORMULA(T15)),AND(NOT(_xlfn.ISFORMULA(U15)),AND(NOT(_xlfn.ISFORMULA(V15)))))))))) -> TRUE | L15: =iferror(SEARCH(P15,F15),-1)>=0 -> FALSE | M15: TRUE | N15: =GOOGLEMAPS_GET_ADDRESS_LATITUDE(F15,true) -> 35.907757 | O15: =GOOGLEMAPS_GET_ADDRESS_LONGITUDE(F15,true) -> 127.76692 | P15: =GOOGLEMAPS_GET_ADDRESS_CITY(F15,true,false) -> Muju | Q15: =GOOGLEMAPS_GET_ADDRESS_STATE(F15,true,false) -> Jeonbuk State | R15: =GOOGLEMAPS_GET_ADDRESS_POSTAL_CODE(F15,false,false) -> 55557 | S15: =GOOGLEMAPS_GET_ADDRESS_COUNTRY(F15,true,false) -> South Korea | T15: =IFERROR(GOOGLEMAPS_DISTANCE("2116 4th Ave, Seattle, WA, 98121", F15, "driving")+0,"Not Driveable") -> Not Driveable | U15: =iferror(GOOGLEMAPS_DURATION("2116 4th Ave, Seattle, WA, 98121", F15, "driving")+0,"Not Driveable") -> Not Driveable | V15: =GOOGLEMAPS_DISTANCE("2116 4th Ave, Seattle, WA, 98121", F15, "flying")+0 -> 5228.6745 | X15: =if(W15="YES","UNKNOWN","N/A") -> N/A | Z15: N/A | AB15: https://magazine.lensvid.com/article/fb/1318327108/mysterious-places-in-the-world-that-are-off-limits-to-everyone-and-why/
A16: 7 - Bucket List | B16: Hashima Island | D16: FEW PLACES IN THE WORLD have a history as odd, or as poignant as Gunkanjima’s. The tiny, fortress-like island (also known as “Hashima” or “Battleship Island”) lies just off the coast of Nagasaki. The island is ringed by a seawall, covered in tightly packed buildings, and entirely abandoned - a ghost town that has been completely uninhabited for more than forty years. In the early 1900s, Gunkanjima was developed by the Mitsubishi Corporation, which believed - correctly - that the island was sitting on a rich submarine coal deposit. For almost the next hundred years, the mine grew deeper and longer, stretching out under the seabed to harvest the coal that was powering Japan’s industrial expansion. By 1941, the island, less than one square kilometer in area, was producing 400,000 tonnes of coal per year. And many of those working slavishly in the undersea mine were forced laborers from Korea. Even more remarkable than the mine was the city that had grown up around it. To accommodate the miners, ten-story apartment complexes were built up on the tiny rock - a high-rise maze linked together by courtyards, corridors, and stairs. There were schools, restaurants, and gaming houses, all encircled by the protective seawall. The island became known as “Midori nashi Shima,” the island without green. Amazingly, by the mid-1950s, it housed almost six thousand people, giving it the highest population density the world has ever known. And then the coal ran out. Mitsubishi closed the mine, everyone left, and this island city was abandoned, left to revert back to nature. The apartments began to crumble, and for the first time, in the barren courtyards, green things started to grow. Broken glass and old newspapers blew over the streets. The sea-breeze whistled through the windows. Now, fifty years later, the island is exactly as it was just after Mitsubishi left. A ghost town in the middle of the sea. From 1974 to 2009, the island was officially closed to all visitors, but recently the intriguing site has been re-opened to organized tours. The site was approved for inclusion on the UNESCO World Heritage list on July 5, 2015. | E16: 3 – Accessible – Tour Guide Required | F16: Hashima Island, Japan | G16: =HYPERLINK(CONCAT("https://www.google.com/maps/search/",F16),"Link") -> Link | H16: Ghost Town | I16: =getCacheString(concat("GMPD|",F16)) -> {"address_components":[{"long_name":"Hashima Island","short_name":"Hashima Island","types":["establishment","natural_feature"]},{"long_name":"Takashimamachi","short_name":"Takashimamachi","types":["political","sublocality","sublocality_level_2"]},{"short_name":"Nagasaki","types":["locality","political"],"long_name":"Nagasaki"},{"short_name":"Nagasaki","types":["administrative_area_level_1","political"],"long_name":"Nagasaki"},{"short_name":"JP","types":["country","political"],"long_name":"Japan"},{"types":["postal_code"],"long_name":"851-1315","short_name":"851-1315"},{"long_name":"2","short_name":"2","types":["premise"]},{"types":["political","sublocality","sublocality_level_2"],"long_name":"Takashimamachi","short_name":"Takashimamachi"},{"long_name":"Nagasaki","types":["locality","political"],"short_name":"Nagasaki"},{"short_name":"Nagasaki","types":["administrative_area_level_1","political"],"long_name":"Nagasaki"},{"long_name":"Japan","short_name":"JP","types":["country","political"]},{"long_name":"851-1315","short_name":"851-1315","types":["postal_code"]},{"types":["latitude"],"long_name":32.6276331,"short_name":32.6276331},{"types":["longitude"],"long_name":129.7385256,"short_name":129.7385256}],"distance_from":{"mi":{"flying":{"2116 4th Ave, Seattle, WA, 98121":5325.824250935167},"driving":{"2116 4th Ave, Seattle, WA, 98121":"GOOGLE_MAPS_ERROR_CACHED - No route found!"}}},"duration_from":{"days":{"driving":{"2116 4th Ave, Seattle, WA, 98121":"GOOGLE_MAPS_ERROR_CACHED - No route found!"}}}} | J16: =GOOGLEMAPS_GET_ADDRESS_COMPONENTS_STRING(F16,false) -> [{"long_name":"Hashima Island","short_name":"Hashima Island","types":["establishment","natural_feature"]},{"long_name":"Takashimamachi","short_name":"Takashimamachi","types":["political","sublocality","sublocality_level_2"]},{"short_name":"Nagasaki","types":["locality","political"],"long_name":"Nagasaki"},{"short_name":"Nagasaki","types":["administrative_area_level_1","political"],"long_name":"Nagasaki"},{"short_name":"JP","types":["country","political"],"long_name":"Japan"},{"types":["postal_code"],"long_name":"851-1315","short_name":"851-1315"},{"long_name":"2","short_name":"2","types":["premise"]},{"types":["political","sublocality","sublocality_level_2"],"long_name":"Takashimamachi","short_name":"Takashimamachi"},{"long_name":"Nagasaki","types":["locality","political"],"short_name":"Nagasaki"},{"short_name":"Nagasaki","types":["administrative_area_level_1","political"],"long_name":"Nagasaki"},{"long_name":"Japan","short_name":"JP","types":["country","political"]},{"long_name":"851-1315","short_name":"851-1315","types":["postal_code"]},{"types":["latitude"],"long_name":32.6276331,"short_name":32.6276331},{"types":["longitude"],"long_name":129.7385256,"short_name":129.7385256},{"types":["debug_info","cache_load_result"],"long_name":"hit","short_name":"hit"}] | K16: =NOT(AND(NOT(_xlfn.ISFORMULA(P16)),AND(NOT(_xlfn.ISFORMULA(Q16)),AND(NOT(_xlfn.ISFORMULA(R16)),AND(NOT(_xlfn.ISFORMULA(S16)),AND(NOT(_xlfn.ISFORMULA(T16)),AND(NOT(_xlfn.ISFORMULA(U16)),AND(NOT(_xlfn.ISFORMULA(V16)))))))))) -> TRUE | L16: =iferror(SEARCH(P16,F16),-1)>=0 -> FALSE | M16: TRUE | N16: =GOOGLEMAPS_GET_ADDRESS_LATITUDE(F16,true) -> 32.627633 | O16: =GOOGLEMAPS_GET_ADDRESS_LONGITUDE(F16,true) -> 129.73853 | P16: =GOOGLEMAPS_GET_ADDRESS_CITY(F16,true,false) -> Nagasaki | Q16: =GOOGLEMAPS_GET_ADDRESS_STATE(F16,true,false) -> Nagasaki | R16: =GOOGLEMAPS_GET_ADDRESS_POSTAL_CODE(F16,false,false) -> 851-1315 | S16: =GOOGLEMAPS_GET_ADDRESS_COUNTRY(F16,true,false) -> Japan | T16: =IFERROR(GOOGLEMAPS_DISTANCE("2116 4th Ave, Seattle, WA, 98121", F16, "driving")+0,"Not Driveable") -> Not Driveable | U16: =iferror(GOOGLEMAPS_DURATION("2116 4th Ave, Seattle, WA, 98121", F16, "driving")+0,"Not Driveable") -> Not Driveable | V16: =GOOGLEMAPS_DISTANCE("2116 4th Ave, Seattle, WA, 98121", F16, "flying")+0 -> 5325.8243 | X16: =if(W16="YES","UNKNOWN","N/A") -> N/A | Z16: N/A | AB16: https://www.atlasobscura.com/places/gubkanjima-island | AF16: Eerie sightseeing spot Hashima Island is an abandoned offshore mining facility, also known as Gunkanjima or Battleship Island. Visitors tour its overgrown industrial sites, semi-ruined concrete workers’ quarters, and so-called “stairway to hell.” There’s a quiet Shinto shrine at the center and views across the East China Sea from atop the perimeter wall. The James Bond film “Skyfall” was partly set on the island.
